Workbook

Sheet Dashboard
B1: INVENTORY & PROCUREMENT OPERATIONS DASHBOARD
B2: Observation Period: Jan 2025 - Dec 2026 | Fictional Company Data | Powered by Excel Formulas
B4: Total PO Spend (INR) | D4: Total POs Issued | F4: Global Late Rate % | H4: Global Reject Rate % | J4: Stockout Risk Count | L4: Excess Stock Count
B5: =SUM(Supplier_Analysis!H2:H9) -> 18561536481 | D5: =SUM(Supplier_Analysis!C2:C9) -> 3500 | F5: =SUM(Supplier_Analysis!F2:F9)/SUM(Supplier_Analysis!E2:E9) -> 0.58938466 | H5: =SUM(Supplier_Analysis!J2:J9)/SUM(Supplier_Analysis!I2:I9) -> 0.006043756 | J5: =COUNTIF(Cleaned_Inventory!J2:J200, "Stockout Risk") -> 25 | L5: =COUNTIF(Cleaned_Inventory!J2:J200, "Excess") -> 20

Sheet KPI_Calculations
A1: Product_Category | B1: Total_PO_Spend_INR
A2: Electronics | B2: =SUMIF(Cleaned_POs!R$2:R$4000, A2, Cleaned_POs!H$2:H$4000) -> 14274393295
A3: Networking | B3: =SUMIF(Cleaned_POs!R$2:R$4000, A3, Cleaned_POs!H$2:H$4000) -> 2875167859
A4: Peripherals | B4: =SUMIF(Cleaned_POs!R$2:R$4000, A4, Cleaned_POs!H$2:H$4000) -> 473563120
A5: Office Furniture | B5: =SUMIF(Cleaned_POs!R$2:R$4000, A5, Cleaned_POs!H$2:H$4000) -> 938412207
A7: Warehouse_ID | B7: Total_PO_Spend_INR
A8: WH-BOM | B8: =SUMIF(Cleaned_POs!P$2:P$4000, A8, Cleaned_POs!H$2:H$4000) -> 4723434998
A9: WH-DEL | B9: =SUMIF(Cleaned_POs!P$2:P$4000, A9, Cleaned_POs!H$2:H$4000) -> 4763091147
A10: WH-BLR | B10: =SUMIF(Cleaned_POs!P$2:P$4000, A10, Cleaned_POs!H$2:H$4000) -> 4241643395
A11: WH-PUN | B11: =SUMIF(Cleaned_POs!P$2:P$4000, A11, Cleaned_POs!H$2:H$4000) -> 4833366941

Sheet Supplier_Analysis
A1: Supplier_ID | B1: Supplier_Name | C1: Total_POs | D1: Open_POs | E1: Delivered_POs | F1: Late_Deliveries | G1: Late_Rate_% | H1: Total_Spend_INR | I1: Total_Received_Qty | J1: Total_Rejected_Qty | K1: Reject_Rate_%
A2: SUP-01 | B2: =VLOOKUP(A2, Lookups!$A$2:$D$10, 2, FALSE()) -> TechSupply Corp | C2: =COUNTIF(Cleaned_POs!$C$2:$C$4000, A2) -> 606 | D2: =COUNTIFS(Cleaned_POs!$C$2:$C$4000, A2, Cleaned_POs!$O$2:$O$4000, "Open") -> 14 | E2: =COUNTIFS(Cleaned_POs!$C$2:$C$4000, A2, Cleaned_POs!$O$2:$O$4000, "Delivered") -> 592 | F2: =COUNTIFS(Cleaned_POs!$C$2:$C$4000, A2, Cleaned_POs!$U$2:$U$4000, "Late") -> 339 | G2: =IF(E2>0, F2/E2, 0) -> 0.57263514 | H2: =SUMIF(Cleaned_POs!$C$2:$C$4000, A2, Cleaned_POs!$H$2:$H$4000) -> 6126257631 | I2: =SUMIF(Cleaned_POs!$C$2:$C$4000, A2, Cleaned_POs!$K$2:$K$4000) -> 75191 | J2: =SUMIF(Cleaned_POs!$C$2:$C$4000, A2, Cleaned_POs!$L$2:$L$4000) -> 518 | K2: =IF(I2>0, J2/I2, 0) -> 0.0068891224
A3: SUP-02 | B3: =VLOOKUP(A3, Lookups!$A$2:$D$10, 2, FALSE()) -> Global Networks | C3: =COUNTIF(Cleaned_POs!$C$2:$C$4000, A3) -> 432 | D3: =COUNTIFS(Cleaned_POs!$C$2:$C$4000, A3, Cleaned_POs!$O$2:$O$4000, "Open") -> 12 | E3: =COUNTIFS(Cleaned_POs!$C$2:$C$4000, A3, Cleaned_POs!$O$2:$O$4000, "Delivered") -> 420 | F3: =COUNTIFS(Cleaned_POs!$C$2:$C$4000, A3, Cleaned_POs!$U$2:$U$4000, "Late") -> 263 | G3: =IF(E3>0, F3/E3, 0) -> 0.62619048 | H3: =SUMIF(Cleaned_POs!$C$2:$C$4000, A3, Cleaned_POs!$H$2:$H$4000) -> 1650042409 | I3: =SUMIF(Cleaned_POs!$C$2:$C$4000, A3, Cleaned_POs!$K$2:$K$4000) -> 53551 | J3: =SUMIF(Cleaned_POs!$C$2:$C$4000, A3, Cleaned_POs!$L$2:$L$4000) -> 232 | K3: =IF(I3>0, J3/I3, 0) -> 0.0043323187
A4: SUP-03 | B4: =VLOOKUP(A4, Lookups!$A$2:$D$10, 2, FALSE()) -> OfficeDepot Pro | C4: =COUNTIF(Cleaned_POs!$C$2:$C$4000, A4) -> 176 | D4: =COUNTIFS(Cleaned_POs!$C$2:$C$4000, A4, Cleaned_POs!$O$2:$O$4000, "Open") -> 6 | E4: =COUNTIFS(Cleaned_POs!$C$2:$C$4000, A4, Cleaned_POs!$O$2:$O$4000, "Delivered") -> 170 | F4: =COUNTIFS(Cleaned_POs!$C$2:$C$4000, A4, Cleaned_POs!$U$2:$U$4000, "Late") -> 106 | G4: =IF(E4>0, F4/E4, 0) -> 0.62352941 | H4: =SUMIF(Cleaned_POs!$C$2:$C$4000, A4, Cleaned_POs!$H$2:$H$4000) -> 100634182 | I4: =SUMIF(Cleaned_POs!$C$2:$C$4000, A4, Cleaned_POs!$K$2:$K$4000) -> 21790 | J4: =SUMIF(Cleaned_POs!$C$2:$C$4000, A4, Cleaned_POs!$L$2:$L$4000) -> 64 | K4: =IF(I4>0, J4/I4, 0) -> 0.0029371271
A5: SUP-04 | B5: =VLOOKUP(A5, Lookups!$A$2:$D$10, 2, FALSE()) -> MegaFurnish | C5: =COUNTIF(Cleaned_POs!$C$2:$C$4000, A5) -> 104 | D5: =COUNTIFS(Cleaned_POs!$C$2:$C$4000, A5, Cleaned_POs!$O$2:$O$4000, "Open") -> 2 | E5: =COUNTIFS(Cleaned_POs!$C$2:$C$4000, A5, Cleaned_POs!$O$2:$O$4000, "Delivered") -> 102 | F5: =COUNTIFS(Cleaned_POs!$C$2:$C$4000, A5, Cleaned_POs!$U$2:$U$4000, "Late") -> 58 | G5: =IF(E5>0, F5/E5, 0) -> 0.56862745 | H5: =SUMIF(Cleaned_POs!$C$2:$C$4000, A5, Cleaned_POs!$H$2:$H$4000) -> 164670349 | I5: =SUMIF(Cleaned_POs!$C$2:$C$4000, A5, Cleaned_POs!$K$2:$K$4000) -> 13998 | J5: =SUMIF(Cleaned_POs!$C$2:$C$4000, A5, Cleaned_POs!$L$2:$L$4000) -> 105 | K5: =IF(I5>0, J5/I5, 0) -> 0.0075010716
A6: SUP-05 | B6: =VLOOKUP(A6, Lookups!$A$2:$D$10, 2, FALSE()) -> FastElectronics | C6: =COUNTIF(Cleaned_POs!$C$2:$C$4000, A6) -> 698 | D6: =COUNTIFS(Cleaned_POs!$C$2:$C$4000, A6, Cleaned_POs!$O$2:$O$4000, "Open") -> 15 | E6: =COUNTIFS(Cleaned_POs!$C$2:$C$4000, A6, Cleaned_POs!$O$2:$O$4000, "Delivered") -> 683 | F6: =COUNTIFS(Cleaned_POs!$C$2:$C$4000, A6, Cleaned_POs!$U$2:$U$4000, "Late") -> 409 | G6: =IF(E6>0, F6/E6, 0) -> 0.5988287 | H6: =SUMIF(Cleaned_POs!$C$2:$C$4000, A6, Cleaned_POs!$H$2:$H$4000) -> 4929772403 | I6: =SUMIF(Cleaned_POs!$C$2:$C$4000, A6, Cleaned_POs!$K$2:$K$4000) -> 88935 | J6: =SUMIF(Cleaned_POs!$C$2:$C$4000, A6, Cleaned_POs!$L$2:$L$4000) -> 589 | K6: =IF(I6>0, J6/I6, 0) -> 0.0066228144
A7: SUP-06 | B7: =VLOOKUP(A7, Lookups!$A$2:$D$10, 2, FALSE()) -> Peripheral Source | C7: =COUNTIF(Cleaned_POs!$C$2:$C$4000, A7) -> 614 | D7: =COUNTIFS(Cleaned_POs!$C$2:$C$4000, A7, Cleaned_POs!$O$2:$O$4000, "Open") -> 7 | E7: =COUNTIFS(Cleaned_POs!$C$2:$C$4000, A7, Cleaned_POs!$O$2:$O$4000, "Delivered") -> 607 | F7: =COUNTIFS(Cleaned_POs!$C$2:$C$4000, A7, Cleaned_POs!$U$2:$U$4000, "Late") -> 342 | G7: =IF(E7>0, F7/E7, 0) -> 0.56342669 | H7: =SUMIF(Cleaned_POs!$C$2:$C$4000, A7, Cleaned_POs!$H$2:$H$4000) -> 372928938 | I7: =SUMIF(Cleaned_POs!$C$2:$C$4000, A7, Cleaned_POs!$K$2:$K$4000) -> 74359 | J7: =SUMIF(Cleaned_POs!$C$2:$C$4000, A7, Cleaned_POs!$L$2:$L$4000) -> 421 | K7: =IF(I7>0, J7/I7, 0) -> 0.0056617222
A8: SUP-07 | B8: =VLOOKUP(A8, Lookups!$A$2:$D$10, 2, FALSE()) -> NextGen Hardware | C8: =COUNTIF(Cleaned_POs!$C$2:$C$4000, A8) -> 506 | D8: =COUNTIFS(Cleaned_POs!$C$2:$C$4000, A8, Cleaned_POs!$O$2:$O$4000, "Open") -> 9 | E8: =COUNTIFS(Cleaned_POs!$C$2:$C$4000, A8, Cleaned_POs!$O$2:$O$4000, "Delivered") -> 497 | F8: =COUNTIFS(Cleaned_POs!$C$2:$C$4000, A8, Cleaned_POs!$U$2:$U$4000, "Late") -> 273 | G8: =IF(E8>0, F8/E8, 0) -> 0.54929577 | H8: =SUMIF(Cleaned_POs!$C$2:$C$4000, A8, Cleaned_POs!$H$2:$H$4000) -> 4443488711 | I8: =SUMIF(Cleaned_POs!$C$2:$C$4000, A8, Cleaned_POs!$K$2:$K$4000) -> 62902 | J8: =SUMIF(Cleaned_POs!$C$2:$C$4000, A8, Cleaned_POs!$L$2:$L$4000) -> 456 | K8: =IF(I8>0, J8/I8, 0) -> 0.007249372
A9: SUP-08 | B9: =VLOOKUP(A9, Lookups!$A$2:$D$10, 2, FALSE()) -> Premium Desks Ltd | C9: =COUNTIF(Cleaned_POs!$C$2:$C$4000, A9) -> 364 | D9: =COUNTIFS(Cleaned_POs!$C$2:$C$4000, A9, Cleaned_POs!$O$2:$O$4000, "Open") -> 6 | E9: =COUNTIFS(Cleaned_POs!$C$2:$C$4000, A9, Cleaned_POs!$O$2:$O$4000, "Delivered") -> 358 | F9: =COUNTIFS(Cleaned_POs!$C$2:$C$4000, A9, Cleaned_POs!$U$2:$U$4000, "Late") -> 231 | G9: =IF(E9>0, F9/E9, 0) -> 0.6452514 | H9: =SUMIF(Cleaned_POs!$C$2:$C$4000, A9, Cleaned_POs!$H$2:$H$4000) -> 773741858 | I9: =SUMIF(Cleaned_POs!$C$2:$C$4000, A9, Cleaned_POs!$K$2:$K$4000) -> 45923 | J9: =SUMIF(Cleaned_POs!$C$2:$C$4000, A9, Cleaned_POs!$L$2:$L$4000) -> 254 | K9: =IF(I9>0, J9/I9, 0) -> 0.0055309975

Sheet Inventory_Analysis
A1: Stock_Status | B1: Count
A2: Healthy | B2: =COUNTIF(Cleaned_Inventory!J2:J200, "Healthy") -> 115
A3: Excess | B3: =COUNTIF(Cleaned_Inventory!J2:J200, "Excess") -> 20
A4: Stockout Risk | B4: =COUNTIF(Cleaned_Inventory!J2:J200, "Stockout Risk") -> 25

Sheet Cleaned_Inventory
A1: SKU | B1: Warehouse_ID | C1: Target_Stock_Qty | D1: Reorder_Level_Qty | E1: Available_Stock_Qty | F1: Product_Name | G1: Category | H1: Unit_Cost | I1: Inventory_Value | J1: Stock_Health_Status
A2: SKU-1001 | B2: WH-BOM | C2: 20 | D2: 8 | E2: 13 | F2: =VLOOKUP(A2, Lookups!$A$12:$E$51, 2, FALSE()) -> Pro Laptop Model U | G2: =VLOOKUP(A2, Lookups!$A$12:$E$51, 3, FALSE()) -> Electronics | H2: =VLOOKUP(A2, Lookups!$A$12:$E$51, 4, FALSE()) -> 59592 | I2: =E2*H2 -> 774696 | J2: =IF(E2<D2, "Stockout Risk", IF(E2>(C2*1.2), "Excess", "Healthy")) -> Healthy
A3: SKU-1001 | B3: WH-DEL | C3: 10 | D3: 4 | E3: 5 | F3: =VLOOKUP(A3, Lookups!$A$12:$E$51, 2, FALSE()) -> Pro Laptop Model U | G3: =VLOOKUP(A3, Lookups!$A$12:$E$51, 3, FALSE()) -> Electronics | H3: =VLOOKUP(A3, Lookups!$A$12:$E$51, 4, FALSE()) -> 59592 | I3: =E3*H3 -> 297960 | J3: =IF(E3<D3, "Stockout Risk", IF(E3>(C3*1.2), "Excess", "Healthy")) -> Healthy
A4: SKU-1001 | B4: WH-BLR | C4: 30 | D4: 12 | E4: 29 | F4: =VLOOKUP(A4, Lookups!$A$12:$E$51, 2, FALSE()) -> Pro Laptop Model U | G4: =VLOOKUP(A4, Lookups!$A$12:$E$51, 3, FALSE()) -> Electronics | H4: =VLOOKUP(A4, Lookups!$A$12:$E$51, 4, FALSE()) -> 59592 | I4: =E4*H4 -> 1728168 | J4: =IF(E4<D4, "Stockout Risk", IF(E4>(C4*1.2), "Excess", "Healthy")) -> Healthy
A5: SKU-1001 | B5: WH-PUN | C5: 30 | D5: 12 | E5: 26 | F5: =VLOOKUP(A5, Lookups!$A$12:$E$51, 2, FALSE()) -> Pro Laptop Model U | G5: =VLOOKUP(A5, Lookups!$A$12:$E$51, 3, FALSE()) -> Electronics | H5: =VLOOKUP(A5, Lookups!$A$12:$E$51, 4, FALSE()) -> 59592 | I5: =E5*H5 -> 1549392 | J5: =IF(E5<D5, "Stockout Risk", IF(E5>(C5*1.2), "Excess", "Healthy")) -> Healthy
A6: SKU-1002 | B6: WH-BOM | C6: 20 | D6: 8 | E6: 22 | F6: =VLOOKUP(A6, Lookups!$A$12:$E$51, 2, FALSE()) -> Pro Laptop Model A | G6: =VLOOKUP(A6, Lookups!$A$12:$E$51, 3, FALSE()) -> Electronics | H6: =VLOOKUP(A6, Lookups!$A$12:$E$51, 4, FALSE()) -> 81048 | I6: =E6*H6 -> 1783056 | J6: =IF(E6<D6, "Stockout Risk", IF(E6>(C6*1.2), "Excess", "Healthy")) -> Healthy
A7: SKU-1002 | B7: WH-DEL | C7: 30 | D7: 12 | E7: 19 | F7: =VLOOKUP(A7, Lookups!$A$12:$E$51, 2, FALSE()) -> Pro Laptop Model A | G7: =VLOOKUP(A7, Lookups!$A$12:$E$51, 3, FALSE()) -> Electronics | H7: =VLOOKUP(A7, Lookups!$A$12:$E$51, 4, FALSE()) -> 81048 | I7: =E7*H7 -> 1539912 | J7: =IF(E7<D7, "Stockout Risk", IF(E7>(C7*1.2), "Excess", "Healthy")) -> Healthy
A8: SKU-1002 | B8: WH-BLR | C8: 30 | D8: 12 | E8: 13 | F8: =VLOOKUP(A8, Lookups!$A$12:$E$51, 2, FALSE()) -> Pro Laptop Model A | G8: =VLOOKUP(A8, Lookups!$A$12:$E$51, 3, FALSE()) -> Electronics | H8: =VLOOKUP(A8, Lookups!$A$12:$E$51, 4, FALSE()) -> 81048 | I8: =E8*H8 -> 1053624 | J8: =IF(E8<D8, "Stockout Risk", IF(E8>(C8*1.2), "Excess", "Healthy")) -> Healthy
A9: SKU-1002 | B9: WH-PUN | C9: 10 | D9: 4 | E9: 9 | F9: =VLOOKUP(A9, Lookups!$A$12:$E$51, 2, FALSE()) -> Pro Laptop Model A | G9: =VLOOKUP(A9, Lookups!$A$12:$E$51, 3, FALSE()) -> Electronics | H9: =VLOOKUP(A9, Lookups!$A$12:$E$51, 4, FALSE()) -> 81048 | I9: =E9*H9 -> 729432 | J9: =IF(E9<D9, "Stockout Risk", IF(E9>(C9*1.2), "Excess", "Healthy")) -> Healthy
A10: SKU-1003 | B10: WH-BOM | C10: 44 | D10: 17 | E10: 30 | F10: =VLOOKUP(A10, Lookups!$A$12:$E$51, 2, FALSE()) -> Enterprise Router 350X | G10: =VLOOKUP(A10, Lookups!$A$12:$E$51, 3, FALSE()) -> Networking | H10: =VLOOKUP(A10, Lookups!$A$12:$E$51, 4, FALSE()) -> 22314 | I10: =E10*H10 -> 669420 | J10: =IF(E10<D10, "Stockout Risk", IF(E10>(C10*1.2), "Excess", "Healthy")) -> Healthy
A11: SKU-1003 | B11: WH-DEL | C11: 66 | D11: 26 | E11: 119 | F11: =VLOOKUP(A11, Lookups!$A$12:$E$51, 2, FALSE()) -> Enterprise Router 350X | G11: =VLOOKUP(A11, Lookups!$A$12:$E$51, 3, FALSE()) -> Networking | H11: =VLOOKUP(A11, Lookups!$A$12:$E$51, 4, FALSE()) -> 22314 | I11: =E11*H11 -> 2655366 | J11: =IF(E11<D11, "Stockout Risk", IF(E11>(C11*1.2), "Excess", "Healthy")) -> Excess
A12: SKU-1003 | B12: WH-BLR | C12: 22 | D12: 8 | E12: 20 | F12: =VLOOKUP(A12, Lookups!$A$12:$E$51, 2, FALSE()) -> Enterprise Router 350X | G12: =VLOOKUP(A12, Lookups!$A$12:$E$51, 3, FALSE()) -> Networking | H12: =VLOOKUP(A12, Lookups!$A$12:$E$51, 4, FALSE()) -> 22314 | I12: =E12*H12 -> 446280 | J12: =IF(E12<D12, "Stockout Risk", IF(E12>(C12*1.2), "Excess", "Healthy")) -> Healthy
A13: SKU-1003 | B13: WH-PUN | C13: 66 | D13: 26 | E13: 42 | F13: =VLOOKUP(A13, Lookups!$A$12:$E$51, 2, FALSE()) -> Enterprise Router 350X | G13: =VLOOKUP(A13, Lookups!$A$12:$E$51, 3, FALSE()) -> Networking | H13: =VLOOKUP(A13, Lookups!$A$12:$E$51, 4, FALSE()) -> 22314 | I13: =E13*H13 -> 937188 | J13: =IF(E13<D13, "Stockout Risk", IF(E13>(C13*1.2), "Excess", "Healthy")) -> Healthy
... A161: SKU-1040 | B161: WH-PUN | C161: 222 | D161: 88 | E161: 231 | F161: =VLOOKUP(A161, Lookups!$A$12:$E$51, 2, FALSE()) -> Wireless Mouse 8 | G161: =VLOOKUP(A161, Lookups!$A$12:$E$51, 3, FALSE()) -> Peripherals | H161: =VLOOKUP(A161, Lookups!$A$12:$E$51, 4, FALSE()) -> 6707 | I161: =E161*H161 -> 1549317 | J161: =IF(E161<D161, "Stockout Risk", IF(E161>(C161*1.2), "Excess", "Healthy")) -> Healthy

Sheet Cleaned_POs
A1: PO_Number | B1: Order_Date | C1: Supplier_ID | D1: SKU | E1: Warehouse_ID | F1: Qty_Ordered | G1: Unit_Cost_INR | H1: Total_Order_Value_INR | I1: Promised_Delivery_Date | J1: Actual_Delivery_Date | K1: Qty_Received | L1: Qty_Rejected | M1: Order_Status | N1: Clean_PO_Number | O1: Clean_Status | P1: Clean_Warehouse | Q1: Supplier_Name_VLOOKUP | R1: Category_XLOOKUP | S1: Imputed_Promised_Date | T1: Days_To_Deliver | U1: Delivery_Status_IF | V1: Rejected_Rate
A2: PO-100001 | B2: 2026-06-16 | C2: SUP-05 | D2: SKU-1025 | E2: WH-DEL | F2: 213 | G2: 26270 | H2: 5595510 | I2: 2026-07-04 | J2: 2026-07-05 | K2: 213 | L2: 0 | M2: Delivered | N2: =TRIM(A2) -> PO-100001 | O2: =PROPER(TRIM(M2)) -> Delivered | P2: =TRIM(E2) -> WH-DEL | Q2: =VLOOKUP(C2, Lookups!$A$2:$D$10, 2, FALSE()) -> FastElectronics | R2: =_xlfn.XLOOKUP(D2, Lookups!$A$12:$A$51, Lookups!$C$12:$C$51, "Unknown") -> Networking | S2: =IF(ISBLANK(I2), B2+VLOOKUP(C2, Lookups!$A$2:$D$10, 4, FALSE()), I2) -> 2026-07-04 | T2: =IF(ISBLANK(J2), "", J2-B2) -> 19 | U2: =IF(O2="Open", "Open", IF(J2>S2, "Late", "On-Time")) -> Late | V2: =IF(K2>0, L2/K2, 0) -> 0
A3: PO-100002 | B3: 2026-09-19 | C3: SUP-01 | D3: SKU-1001 | E3: WH-BOM | F3: 142 | G3: 59592 | H3: 8462064 | I3: 2026-10-03 | J3: 2026-10-03 | K3: 142 | L3: 0 | M3: Delivered | N3: =TRIM(A3) -> PO-100002 | O3: =PROPER(TRIM(M3)) -> Delivered | P3: =TRIM(E3) -> WH-BOM | Q3: =VLOOKUP(C3, Lookups!$A$2:$D$10, 2, FALSE()) -> TechSupply Corp | R3: =_xlfn.XLOOKUP(D3, Lookups!$A$12:$A$51, Lookups!$C$12:$C$51, "Unknown") -> Electronics | S3: =IF(ISBLANK(I3), B3+VLOOKUP(C3, Lookups!$A$2:$D$10, 4, FALSE()), I3) -> 2026-10-03 | T3: =IF(ISBLANK(J3), "", J3-B3) -> 14 | U3: =IF(O3="Open", "Open", IF(J3>S3, "Late", "On-Time")) -> On-Time | V3: =IF(K3>0, L3/K3, 0) -> 0
A4: PO-100003 | B4: 2025-01-03 | C4: SUP-01 | D4: SKU-1002 | E4: WH-BOM | F4: 108 | G4: 81048 | H4: 8753184 | I4: 2025-01-17 | J4: 2025-01-17 | K4: 108 | L4: 0 | M4: Delivered | N4: =TRIM(A4) -> PO-100003 | O4: =PROPER(TRIM(M4)) -> Delivered | P4: =TRIM(E4) -> WH-BOM | Q4: =VLOOKUP(C4, Lookups!$A$2:$D$10, 2, FALSE()) -> TechSupply Corp | R4: =_xlfn.XLOOKUP(D4, Lookups!$A$12:$A$51, Lookups!$C$12:$C$51, "Unknown") -> Electronics | S4: =IF(ISBLANK(I4), B4+VLOOKUP(C4, Lookups!$A$2:$D$10, 4, FALSE()), I4) -> 2025-01-17 | T4: =IF(ISBLANK(J4), "", J4-B4) -> 14 | U4: =IF(O4="Open", "Open", IF(J4>S4, "Late", "On-Time")) -> On-Time | V4: =IF(K4>0, L4/K4, 0) -> 0
A5: PO-100004 | B5: 2026-05-22 | C5: SUP-02 | D5: SKU-1013 | E5: WH-PUN | F5: 199 | G5: 36295 | H5: 7222705 | I5: 2026-06-12 | J5: 2026-06-13 | K5: 199 | L5: 0 | M5: Delivered | N5: =TRIM(A5) -> PO-100004 | O5: =PROPER(TRIM(M5)) -> Delivered | P5: =TRIM(E5) -> WH-PUN | Q5: =VLOOKUP(C5, Lookups!$A$2:$D$10, 2, FALSE()) -> Global Networks | R5: =_xlfn.XLOOKUP(D5, Lookups!$A$12:$A$51, Lookups!$C$12:$C$51, "Unknown") -> Networking | S5: =IF(ISBLANK(I5), B5+VLOOKUP(C5, Lookups!$A$2:$D$10, 4, FALSE()), I5) -> 2026-06-12 | T5: =IF(ISBLANK(J5), "", J5-B5) -> 22 | U5: =IF(O5="Open", "Open", IF(J5>S5, "Late", "On-Time")) -> Late | V5: =IF(K5>0, L5/K5, 0) -> 0
A6: PO-100005 | B6: 2026-02-02 | C6: SUP-01 | D6: SKU-1001 | E6: WH-BLR | F6: 86 | G6: 59592 | H6: 5124912 | I6: 2026-02-16 | J6: 2026-02-16 | K6: 86 | L6: 0 | M6: Delivered | N6: =TRIM(A6) -> PO-100005 | O6: =PROPER(TRIM(M6)) -> Delivered | P6: =TRIM(E6) -> WH-BLR | Q6: =VLOOKUP(C6, Lookups!$A$2:$D$10, 2, FALSE()) -> TechSupply Corp | R6: =_xlfn.XLOOKUP(D6, Lookups!$A$12:$A$51, Lookups!$C$12:$C$51, "Unknown") -> Electronics | S6: =IF(ISBLANK(I6), B6+VLOOKUP(C6, Lookups!$A$2:$D$10, 4, FALSE()), I6) -> 2026-02-16 | T6: =IF(ISBLANK(J6), "", J6-B6) -> 14 | U6: =IF(O6="Open", "Open", IF(J6>S6, "Late", "On-Time")) -> On-Time | V6: =IF(K6>0, L6/K6, 0) -> 0
A7: PO-100006 | B7: 2026-07-15 | C7: SUP-08 | D7: SKU-1028 | E7: WH-PUN | F7: 76 | G7: 23054 | H7: 1752104 | I7: 2026-07-27 | J7: 2026-07-27 | K7: 76 | L7: 0 | M7: Delivered | N7: =TRIM(A7) -> PO-100006 | O7: =PROPER(TRIM(M7)) -> Delivered | P7: =TRIM(E7) -> WH-PUN | Q7: =VLOOKUP(C7, Lookups!$A$2:$D$10, 2, FALSE()) -> Premium Desks Ltd | R7: =_xlfn.XLOOKUP(D7, Lookups!$A$12:$A$51, Lookups!$C$12:$C$51, "Unknown") -> Office Furniture | S7: =IF(ISBLANK(I7), B7+VLOOKUP(C7, Lookups!$A$2:$D$10, 4, FALSE()), I7) -> 2026-07-27 | T7: =IF(ISBLANK(J7), "", J7-B7) -> 12 | U7: =IF(O7="Open", "Open", IF(J7>S7, "Late", "On-Time")) -> On-Time | V7: =IF(K7>0, L7/K7, 0) -> 0
A8: PO-100007 | B8: 2026-08-27 | C8: SUP-03 | D8: SKU-1033 | E8: WH-BLR | F8: 185 | G8: 7271 | H8: 1345135 | I8: 2026-09-03 | J8: 2026-09-02 | K8: 185 | L8: 0 | M8: Delivered | N8: =TRIM(A8) -> PO-100007 | O8: =PROPER(TRIM(M8)) -> Delivered | P8: =TRIM(E8) -> WH-BLR | Q8: =VLOOKUP(C8, Lookups!$A$2:$D$10, 2, FALSE()) -> OfficeDepot Pro | R8: =_xlfn.XLOOKUP(D8, Lookups!$A$12:$A$51, Lookups!$C$12:$C$51, "Unknown") -> Peripherals | S8: =IF(ISBLANK(I8), B8+VLOOKUP(C8, Lookups!$A$2:$D$10, 4, FALSE()), I8) -> 2026-09-03 | T8: =IF(ISBLANK(J8), "", J8-B8) -> 6 | U8: =IF(O8="Open", "Open", IF(J8>S8, "Late", "On-Time")) -> On-Time | V8: =IF(K8>0, L8/K8, 0) -> 0
A9: PO-100008 | B9: 2025-09-08 | C9: SUP-05 | D9: SKU-1029 | E9: WH-BOM | F9: 247 | G9: 19090 | H9: 4715230 | I9: 2025-09-26 | J9: 2025-09-29 | K9: 247 | L9: 0 | M9: Delivered | N9: =TRIM(A9) -> PO-100008 | O9: =PROPER(TRIM(M9)) -> Delivered | P9: =TRIM(E9) -> WH-BOM | Q9: =VLOOKUP(C9, Lookups!$A$2:$D$10, 2, FALSE()) -> FastElectronics | R9: =_xlfn.XLOOKUP(D9, Lookups!$A$12:$A$51, Lookups!$C$12:$C$51, "Unknown") -> Networking | S9: =IF(ISBLANK(I9), B9+VLOOKUP(C9, Lookups!$A$2:$D$10, 4, FALSE()), I9) -> 2025-09-26 | T9: =IF(ISBLANK(J9), "", J9-B9) -> 21 | U9: =IF(O9="Open", "Open", IF(J9>S9, "Late", "On-Time")) -> Late | V9: =IF(K9>0, L9/K9, 0) -> 0
A10: PO-100009 | B10: 2026-07-23 | C10: SUP-06 | D10: SKU-1024 | E10: WH-BLR | F10: 94 | G10: 4440 | H10: 417360 | I10: 2026-08-02 | J10: 2026-08-03 | K10: 94 | L10: 11 | M10: Delivered | N10: =TRIM(A10) -> PO-100009 | O10: =PROPER(TRIM(M10)) -> Delivered | P10: =TRIM(E10) -> WH-BLR | Q10: =VLOOKUP(C10, Lookups!$A$2:$D$10, 2, FALSE()) -> Peripheral Source | R10: =_xlfn.XLOOKUP(D10, Lookups!$A$12:$A$51, Lookups!$C$12:$C$51, "Unknown") -> Peripherals | S10: =IF(ISBLANK(I10), B10+VLOOKUP(C10, Lookups!$A$2:$D$10, 4, FALSE()), I10) -> 2026-08-02 | T10: =IF(ISBLANK(J10), "", J10-B10) -> 11 | U10: =IF(O10="Open", "Open", IF(J10>S10, "Late", "On-Time")) -> Late | V10: =IF(K10>0, L10/K10, 0) -> 0.11702128
A11: PO-100010 | B11: 2025-09-24 | C11: SUP-01 | D11: SKU-1001 | E11: WH-BOM | F11: 102 | G11: 59592 | H11: 6078384 | I11: 2025-10-08 | J11: 2025-10-05 | K11: 102 | L11: 0 | M11: Delivered | N11: =TRIM(A11) -> PO-100010 | O11: =PROPER(TRIM(M11)) -> Delivered | P11: =TRIM(E11) -> WH-BOM | Q11: =VLOOKUP(C11, Lookups!$A$2:$D$10, 2, FALSE()) -> TechSupply Corp | R11: =_xlfn.XLOOKUP(D11, Lookups!$A$12:$A$51, Lookups!$C$12:$C$51, "Unknown") -> Electronics | S11: =IF(ISBLANK(I11), B11+VLOOKUP(C11, Lookups!$A$2:$D$10, 4, FALSE()), I11) -> 2025-10-08 | T11: =IF(ISBLANK(J11), "", J11-B11) -> 11 | U11: =IF(O11="Open", "Open", IF(J11>S11, "Late", "On-Time")) -> On-Time | V11: =IF(K11>0, L11/K11, 0) -> 0
A12: PO-100011 | B12: 2026-04-03 | C12: SUP-06 | D12: SKU-1021 | E12: WH-PUN | F12: 157 | G12: 7754 | H12: 1217378 | I12: 2026-04-13 | J12: 2026-04-14 | K12: 157 | L12: 0 | M12: Delivered | N12: =TRIM(A12) -> PO-100011 | O12: =PROPER(TRIM(M12)) -> Delivered | P12: =TRIM(E12) -> WH-PUN | Q12: =VLOOKUP(C12, Lookups!$A$2:$D$10, 2, FALSE()) -> Peripheral Source | R12: =_xlfn.XLOOKUP(D12, Lookups!$A$12:$A$51, Lookups!$C$12:$C$51, "Unknown") -> Peripherals | S12: =IF(ISBLANK(I12), B12+VLOOKUP(C12, Lookups!$A$2:$D$10, 4, FALSE()), I12) -> 2026-04-13 | T12: =IF(ISBLANK(J12), "", J12-B12) -> 11 | U12: =IF(O12="Open", "Open", IF(J12>S12, "Late", "On-Time")) -> Late | V12: =IF(K12>0, L12/K12, 0) -> 0
A13: PO-100012 | B13: 2025-10-07 | C13: SUP-02 | D13: SKU-1026 | E13: WH-PUN | F13: 123 | G13: 23667 | H13: 2911041 | I13: 2025-10-28 | J13: 2025-10-30 | K13: 96 | L13: 0 | M13: Delivered | N13: =TRIM(A13) -> PO-100012 | O13: =PROPER(TRIM(M13)) -> Delivered | P13: =TRIM(E13) -> WH-PUN | Q13: =VLOOKUP(C13, Lookups!$A$2:$D$10, 2, FALSE()) -> Global Networks | R13: =_xlfn.XLOOKUP(D13, Lookups!$A$12:$A$51, Lookups!$C$12:$C$51, "Unknown") -> Networking | S13: =IF(ISBLANK(I13), B13+VLOOKUP(C13, Lookups!$A$2:$D$10, 4, FALSE()), I13) -> 2025-10-28 | T13: =IF(ISBLANK(J13), "", J13-B13) -> 23 | U13: =IF(O13="Open", "Open", IF(J13>S13, "Late", "On-Time")) -> Late | V13: =IF(K13>0, L13/K13, 0) -> 0
... A52: PO-100051 | B52: 2025-08-17 | C52: SUP-05 | D52: SKU-1022 | E52: WH-DEL | F52: 190 | G52: 58396 | H52: 11095240 | I52: 2025-09-04 | J52: 2025-09-13 | K52: 190 | L52: 0 | M52: Delivered | N52: =TRIM(A52) -> PO-100051 | O52: =PROPER(TRIM(M52)) -> Delivered | P52: =TRIM(E52) -> WH-DEL | Q52: =VLOOKUP(C52, Lookups!$A$2:$D$10, 2, FALSE()) -> FastElectronics | R52: =_xlfn.XLOOKUP(D52, Lookups!$A$12:$A$51, Lookups!$C$12:$C$51, "Unknown") -> Electronics | S52: =IF(ISBLANK(I52), B52+VLOOKUP(C52, Lookups!$A$2:$D$10, 4, FALSE()), I52) -> 2025-09-04 | T52: =IF(ISBLANK(J52), "", J52-B52) -> 27 | U52: =IF(O52="Open", "Open", IF(J52>S52, "Late", "On-Time")) -> Late | V52: =IF(K52>0, L52/K52, 0) -> 0
A53: PO-100052 | B53: 2026-11-24 | C53: SUP-05 | D53: SKU-1029 | E53: WH-BOM | F53: 130 | G53: 19090 | H53: 2481700 | K53: 0 | L53: 0 | M53: Open | N53: =TRIM(A53) -> PO-100052 | O53: =PROPER(TRIM(M53)) -> Open | P53: =TRIM(E53) -> WH-BOM | Q53: =VLOOKUP(C53, Lookups!$A$2:$D$10, 2, FALSE()) -> FastElectronics | R53: =_xlfn.XLOOKUP(D53, Lookups!$A$12:$A$51, Lookups!$C$12:$C$51, "Unknown") -> Networking | S53: =IF(ISBLANK(I53), B53+VLOOKUP(C53, Lookups!$A$2:$D$10, 4, FALSE()), I53) -> 46368 | T53: =IF(ISBLANK(J53), "", J53-B53) | U53: =IF(O53="Open", "Open", IF(J53>S53, "Late", "On-Time")) -> Open | V53: =IF(K53>0, L53/K53, 0) -> 0
A54: PO-100053 | B54: 2025-02-27 | C54: SUP-02 | D54: SKU-1015 | E54: WH-PUN | F54: 38 | G54: 29719 | H54: 1129322 | I54: 2025-03-20 | J54: 2025-03-20 | K54: 38 | L54: 0 | M54: delivered | N54: =TRIM(A54) -> PO-100053 | O54: =PROPER(TRIM(M54)) -> Delivered | P54: =TRIM(E54) -> WH-PUN | Q54: =VLOOKUP(C54, Lookups!$A$2:$D$10, 2, FALSE()) -> Global Networks | R54: =_xlfn.XLOOKUP(D54, Lookups!$A$12:$A$51, Lookups!$C$12:$C$51, "Unknown") -> Networking | S54: =IF(ISBLANK(I54), B54+VLOOKUP(C54, Lookups!$A$2:$D$10, 4, FALSE()), I54) -> 2025-03-20 | T54: =IF(ISBLANK(J54), "", J54-B54) -> 21 | U54: =IF(O54="Open", "Open", IF(J54>S54, "Late", "On-Time")) -> On-Time | V54: =IF(K54>0, L54/K54, 0) -> 0
A55: PO-100054 | B55: 2026-06-09 | C55: SUP-01 | D55: SKU-1008 | E55: WH-PUN | F55: 223 | G55: 48905 | H55: 10905815 | I55: 2026-06-23 | J55: 2026-06-28 | K55: 223 | L55: 0 | M55: Delivered | N55: =TRIM(A55) -> PO-100054 | O55: =PROPER(TRIM(M55)) -> Delivered | P55: =TRIM(E55) -> WH-PUN | Q55: =VLOOKUP(C55, Lookups!$A$2:$D$10, 2, FALSE()) -> TechSupply Corp | R55: =_xlfn.XLOOKUP(D55, Lookups!$A$12:$A$51, Lookups!$C$12:$C$51, "Unknown") -> Electronics | S55: =IF(ISBLANK(I55), B55+VLOOKUP(C55, Lookups!$A$2:$D$10, 4, FALSE()), I55) -> 2026-06-23 | T55: =IF(ISBLANK(J55), "", J55-B55) -> 19 | U55: =IF(O55="Open", "Open", IF(J55>S55, "Late", "On-Time")) -> Late | V55: =IF(K55>0, L55/K55, 0) -> 0
A56: PO-100055 | B56: 2026-08-26 | C56: SUP-05 | D56: SKU-1025 | E56: WH-BLR | F56: 133 | G56: 26270 | H56: 3493910 | I56: 2026-09-13 | J56: 2026-09-13 | K56: 133 | L56: 0 | M56: Delivered | N56: =TRIM(A56) -> PO-100055 | O56: =PROPER(TRIM(M56)) -> Delivered | P56: =TRIM(E56) -> WH-BLR | Q56: =VLOOKUP(C56, Lookups!$A$2:$D$10, 2, FALSE()) -> FastElectronics | R56: =_xlfn.XLOOKUP(D56, Lookups!$A$12:$A$51, Lookups!$C$12:$C$51, "Unknown") -> Networking | S56: =IF(ISBLANK(I56), B56+VLOOKUP(C56, Lookups!$A$2:$D$10, 4, FALSE()), I56) -> 2026-09-13 | T56: =IF(ISBLANK(J56), "", J56-B56) -> 18 | U56: =IF(O56="Open", "Open", IF(J56>S56, "Late", "On-Time")) -> On-Time | V56: =IF(K56>0, L56/K56, 0) -> 0
A57: PO-100056 | B57: 2025-08-21 | C57: SUP-05 | D57: SKU-1003 | E57: WH-PUN | F57: 234 | G57: 22314 | H57: 5221476 | I57: 2025-09-08 | J57: 2025-09-08 | K57: 234 | L57: 19 | M57: Delivered | N57: =TRIM(A57) -> PO-100056 | O57: =PROPER(TRIM(M57)) -> Delivered | P57: =TRIM(E57) -> WH-PUN | Q57: =VLOOKUP(C57, Lookups!$A$2:$D$10, 2, FALSE()) -> FastElectronics | R57: =_xlfn.XLOOKUP(D57, Lookups!$A$12:$A$51, Lookups!$C$12:$C$51, "Unknown") -> Networking | S57: =IF(ISBLANK(I57), B57+VLOOKUP(C57, Lookups!$A$2:$D$10, 4, FALSE()), I57) -> 2025-09-08 | T57: =IF(ISBLANK(J57), "", J57-B57) -> 18 | U57: =IF(O57="Open", "Open", IF(J57>S57, "Late", "On-Time")) -> On-Time | V57: =IF(K57>0, L57/K57, 0) -> 0.081196581
A58: PO-100057 | B58: 2026-07-15 | C58: SUP-01 | D58: SKU-1001 | E58: WH-BLR | F58: 210 | G58: 59592 | H58: 12514320 | I58: 2026-07-29 | J58: 2026-07-29 | K58: 188 | L58: 0 | M58: Delivered | N58: =TRIM(A58) -> PO-100057 | O58: =PROPER(TRIM(M58)) -> Delivered | P58: =TRIM(E58) -> WH-BLR | Q58: =VLOOKUP(C58, Lookups!$A$2:$D$10, 2, FALSE()) -> TechSupply Corp | R58: =_xlfn.XLOOKUP(D58, Lookups!$A$12:$A$51, Lookups!$C$12:$C$51, "Unknown") -> Electronics | S58: =IF(ISBLANK(I58), B58+VLOOKUP(C58, Lookups!$A$2:$D$10, 4, FALSE()), I58) -> 2026-07-29 | T58: =IF(ISBLANK(J58), "", J58-B58) -> 14 | U58: =IF(O58="Open", "Open", IF(J58>S58, "Late", "On-Time")) -> On-Time | V58: =IF(K58>0, L58/K58, 0) -> 0
A59: PO-100058 | B59: 2025-10-28 | C59: SUP-02 | D59: SKU-1013 | E59: WH-DEL | F59: 64 | G59: 36295 | H59: 2322880 | I59: 2025-11-18 | J59: 2025-11-18 | K59: 64 | L59: 0 | M59: Delivered | N59: =TRIM(A59) -> PO-100058 | O59: =PROPER(TRIM(M59)) -> Delivered | P59: =TRIM(E59) -> WH-DEL | Q59: =VLOOKUP(C59, Lookups!$A$2:$D$10, 2, FALSE()) -> Global Networks | R59: =_xlfn.XLOOKUP(D59, Lookups!$A$12:$A$51, Lookups!$C$12:$C$51, "Unknown") -> Networking | S59: =IF(ISBLANK(I59), B59+VLOOKUP(C59, Lookups!$A$2:$D$10, 4, FALSE()), I59) -> 2025-11-18 | T59: =IF(ISBLANK(J59), "", J59-B59) -> 21 | U59: =IF(O59="Open", "Open", IF(J59>S59, "Late", "On-Time")) -> On-Time | V59: =IF(K59>0, L59/K59, 0) -> 0
A60: PO-100059 | B60: 2026-02-05 | C60: SUP-04 | D60: SKU-1038 | E60: WH-BOM | F60: 212 | G60: 11309 | H60: 2397508 | I60: 2026-03-07 | J60: 2026-03-08 | K60: 212 | L60: 0 | M60: Delivered | N60: =TRIM(A60) -> PO-100059 | O60: =PROPER(TRIM(M60)) -> Delivered | P60: =TRIM(E60) -> WH-BOM | Q60: =VLOOKUP(C60, Lookups!$A$2:$D$10, 2, FALSE()) -> MegaFurnish | R60: =_xlfn.XLOOKUP(D60, Lookups!$A$12:$A$51, Lookups!$C$12:$C$51, "Unknown") -> Office Furniture | S60: =IF(ISBLANK(I60), B60+VLOOKUP(C60, Lookups!$A$2:$D$10, 4, FALSE()), I60) -> 2026-03-07 | T60: =IF(ISBLANK(J60), "", J60-B60) -> 31 | U60: =IF(O60="Open", "Open", IF(J60>S60, "Late", "On-Time")) -> Late | V60: =IF(K60>0, L60/K60, 0) -> 0
A61: PO-100060 | B61: 2025-09-23 | C61: SUP-02 | D61: SKU-1026 | E61: WH-PUN | F61: 15 | G61: 23667 | H61: 355005 | I61: 2025-10-14 | J61: 2025-10-15 | K61: 15 | L61: 0 | M61: Delivered | N61: =TRIM(A61) -> PO-100060 | O61: =PROPER(TRIM(M61)) -> Delivered | P61: =TRIM(E61) -> WH-PUN | Q61: =VLOOKUP(C61, Lookups!$A$2:$D$10, 2, FALSE()) -> Global Networks | R61: =_xlfn.XLOOKUP(D61, Lookups!$A$12:$A$51, Lookups!$C$12:$C$51, "Unknown") -> Networking | S61: =IF(ISBLANK(I61), B61+VLOOKUP(C61, Lookups!$A$2:$D$10, 4, FALSE()), I61) -> 2025-10-14 | T61: =IF(ISBLANK(J61), "", J61-B61) -> 22 | U61: =IF(O61="Open", "Open", IF(J61>S61, "Late", "On-Time")) -> Late | V61: =IF(K61>0, L61/K61, 0) -> 0
A62: PO-100061 | B62: 2026-03-24 | C62: SUP-06 | D62: SKU-1040 | E62: WH-BOM | F62: 72 | G62: 6707 | H62: 482904 | I62: 2026-04-03 | J62: 2026-04-04 | K62: 72 | L62: 0 | M62: Delivered | N62: =TRIM(A62) -> PO-100061 | O62: =PROPER(TRIM(M62)) -> Delivered | P62: =TRIM(E62) -> WH-BOM | Q62: =VLOOKUP(C62, Lookups!$A$2:$D$10, 2, FALSE()) -> Peripheral Source | R62: =_xlfn.XLOOKUP(D62, Lookups!$A$12:$A$51, Lookups!$C$12:$C$51, "Unknown") -> Peripherals | S62: =IF(ISBLANK(I62), B62+VLOOKUP(C62, Lookups!$A$2:$D$10, 4, FALSE()), I62) -> 2026-04-03 | T62: =IF(ISBLANK(J62), "", J62-B62) -> 11 | U62: =IF(O62="Open", "Open", IF(J62>S62, "Late", "On-Time")) -> Late | V62: =IF(K62>0, L62/K62, 0) -> 0
A63: PO-100062 | B63: 2025-05-26 | C63: SUP-06 | D63: SKU-1006 | E63: WH-BLR | F63: 24 | G63: 2212 | H63: 53088 | I63: 2025-06-05 | J63: 2025-06-06 | K63: 24 | L63: 0 | M63: Delivered | N63: =TRIM(A63) -> PO-100062 | O63: =PROPER(TRIM(M63)) -> Delivered | P63: =TRIM(E63) -> WH-BLR | Q63: =VLOOKUP(C63, Lookups!$A$2:$D$10, 2, FALSE()) -> Peripheral Source | R63: =_xlfn.XLOOKUP(D63, Lookups!$A$12:$A$51, Lookups!$C$12:$C$51, "Unknown") -> Peripherals | S63: =IF(ISBLANK(I63), B63+VLOOKUP(C63, Lookups!$A$2:$D$10, 4, FALSE()), I63) -> 2025-06-05 | T63: =IF(ISBLANK(J63), "", J63-B63) -> 11 | U63: =IF(O63="Open", "Open", IF(J63>S63, "Late", "On-Time")) -> Late | V63: =IF(K63>0, L63/K63, 0) -> 0
A64: PO-100063 | B64: 2026-02-02 | C64: SUP-02 | D64: SKU-1005 | E64: WH-BOM | F64: 132 | G64: 39270 | H64: 5183640 | I64: 2026-02-23 | J64: 2026-02-23 | K64: 132 | L64: 17 | M64: Delivered | N64: =TRIM(A64) -> PO-100063 | O64: =PROPER(TRIM(M64)) -> Delivered | P64: =TRIM(E64) -> WH-BOM | Q64: =VLOOKUP(C64, Lookups!$A$2:$D$10, 2, FALSE()) -> Global Networks | R64: =_xlfn.XLOOKUP(D64, Lookups!$A$12:$A$51, Lookups!$C$12:$C$51, "Unknown") -> Networking | S64: =IF(ISBLANK(I64), B64+VLOOKUP(C64, Lookups!$A$2:$D$10, 4, FALSE()), I64) -> 2026-02-23 | T64: =IF(ISBLANK(J64), "", J64-B64) -> 21 | U64: =IF(O64="Open", "Open", IF(J64>S64, "Late", "On-Time")) -> On-Time | V64: =IF(K64>0, L64/K64, 0) -> 0.12878788
A65: PO-100064 | B65: 2025-09-22 | C65: SUP-07 | D65: SKU-1011 | E65: WH-BLR | F65: 227 | G65: 48478 | H65: 11004506 | I65: 2025-10-16 | J65: 2025-10-12 | K65: 227 | L65: 0 | M65: Delivered | N65: =TRIM(A65) -> PO-100064 | O65: =PROPER(TRIM(M65)) -> Delivered | P65: =TRIM(E65) -> WH-BLR | Q65: =VLOOKUP(C65, Lookups!$A$2:$D$10, 2, FALSE()) -> NextGen Hardware | R65: =_xlfn.XLOOKUP(D65, Lookups!$A$12:$A$51, Lookups!$C$12:$C$51, "Unknown") -> Electronics | S65: =IF(ISBLANK(I65), B65+VLOOKUP(C65, Lookups!$A$2:$D$10, 4, FALSE()), I65) -> 2025-10-16 | T65: =IF(ISBLANK(J65), "", J65-B65) -> 20 | U65: =IF(O65="Open", "Open", IF(J65>S65, "Late", "On-Time")) -> On-Time | V65: =IF(K65>0, L65/K65, 0) -> 0
... A187: PO-100186 | B187: 2025-11-12 | C187: SUP-06 | D187: SKU-1040 | E187: WH-BLR | F187: 53 | G187: 6707 | H187: 355471 | I187: 2025-11-22 | J187: 2025-11-23 | K187: 53 | L187: 0 | M187: Delivered | N187: =TRIM(A187) -> PO-100186 | O187: =PROPER(TRIM(M187)) -> Delivered | P187: =TRIM(E187) -> WH-BLR | Q187: =VLOOKUP(C187, Lookups!$A$2:$D$10, 2, FALSE()) -> Peripheral Source | R187: =_xlfn.XLOOKUP(D187, Lookups!$A$12:$A$51, Lookups!$C$12:$C$51, "Unknown") -> Peripherals | S187: =IF(ISBLANK(I187), B187+VLOOKUP(C187, Lookups!$A$2:$D$10, 4, FALSE()), I187) -> 2025-11-22 | T187: =IF(ISBLANK(J187), "", J187-B187) -> 11 | U187: =IF(O187="Open", "Open", IF(J187>S187, "Late", "On-Time")) -> Late | V187: =IF(K187>0, L187/K187, 0) -> 0
A188: PO-100187 | B188: 2026-12-14 | C188: SUP-04 | D188: SKU-1038 | E188: WH-DEL | F188: 236 | G188: 11309 | H188: 2668924 | I188: 2027-01-13 | K188: 0 | L188: 0 | M188: Open | N188: =TRIM(A188) -> PO-100187 | O188: =PROPER(TRIM(M188)) -> Open | P188: =TRIM(E188) -> WH-DEL | Q188: =VLOOKUP(C188, Lookups!$A$2:$D$10, 2, FALSE()) -> MegaFurnish | R188: =_xlfn.XLOOKUP(D188, Lookups!$A$12:$A$51, Lookups!$C$12:$C$51, "Unknown") -> Office Furniture | S188: =IF(ISBLANK(I188), B188+VLOOKUP(C188, Lookups!$A$2:$D$10, 4, FALSE()), I188) -> 2027-01-13 | T188: =IF(ISBLANK(J188), "", J188-B188) | U188: =IF(O188="Open", "Open", IF(J188>S188, "Late", "On-Time")) -> Open | V188: =IF(K188>0, L188/K188, 0) -> 0
A189: PO-100188 | B189: 2025-12-01 | C189: SUP-07 | D189: SKU-1020 | E189: WH-BOM | F189: 38 | G189: 65379 | H189: 2484402 | I189: 2025-12-25 | J189: 2025-12-26 | K189: 38 | L189: 0 | M189: Delivered | N189: =TRIM(A189) -> PO-100188 | O189: =PROPER(TRIM(M189)) -> Delivered | P189: =TRIM(E189) -> WH-BOM | Q189: =VLOOKUP(C189, Lookups!$A$2:$D$10, 2, FALSE()) -> NextGen Hardware | R189: =_xlfn.XLOOKUP(D189, Lookups!$A$12:$A$51, Lookups!$C$12:$C$51, "Unknown") -> Electronics | S189: =IF(ISBLANK(I189), B189+VLOOKUP(C189, Lookups!$A$2:$D$10, 4, FALSE()), I189) -> 2025-12-25 | T189: =IF(ISBLANK(J189), "", J189-B189) -> 25 | U189: =IF(O189="Open", "Open", IF(J189>S189, "Late", "On-Time")) -> Late | V189: =IF(K189>0, L189/K189, 0) -> 0
A190: PO-100189 | B190: 2026-09-06 | C190: SUP-07 | D190: SKU-1012 | E190: WH-BOM | F190: 167 | G190: 71062 | H190: 11867354 | I190: 2026-09-30 | J190: 2026-10-01 | K190: 167 | L190: 0 | M190: Delivered | N190: =TRIM(A190) -> PO-100189 | O190: =PROPER(TRIM(M190)) -> Delivered | P190: =TRIM(E190) -> WH-BOM | Q190: =VLOOKUP(C190, Lookups!$A$2:$D$10, 2, FALSE()) -> NextGen Hardware | R190: =_xlfn.XLOOKUP(D190, Lookups!$A$12:$A$51, Lookups!$C$12:$C$51, "Unknown") -> Electronics | S190: =IF(ISBLANK(I190), B190+VLOOKUP(C190, Lookups!$A$2:$D$10, 4, FALSE()), I190) -> 2026-09-30 | T190: =IF(ISBLANK(J190), "", J190-B190) -> 25 | U190: =IF(O190="Open", "Open", IF(J190>S190, "Late", "On-Time")) -> Late | V190: =IF(K190>0, L190/K190, 0) -> 0
A191: PO-100190 | B191: 2026-09-14 | C191: SUP-02 | D191: SKU-1034 | E191: WH-DEL | F191: 79 | G191: 16501 | H191: 1303579 | I191: 2026-10-05 | J191: 2026-10-06 | K191: 79 | L191: 0 | M191: Delivered | N191: =TRIM(A191) -> PO-100190 | O191: =PROPER(TRIM(M191)) -> Delivered | P191: =TRIM(E191) -> WH-DEL | Q191: =VLOOKUP(C191, Lookups!$A$2:$D$10, 2, FALSE()) -> Global Networks | R191: =_xlfn.XLOOKUP(D191, Lookups!$A$12:$A$51, Lookups!$C$12:$C$51, "Unknown") -> Networking | S191: =IF(ISBLANK(I191), B191+VLOOKUP(C191, Lookups!$A$2:$D$10, 4, FALSE()), I191) -> 2026-10-05 | T191: =IF(ISBLANK(J191), "", J191-B191) -> 22 | U191: =IF(O191="Open", "Open", IF(J191>S191, "Late", "On-Time")) -> Late | V191: =IF(K191>0, L191/K191, 0) -> 0
A192: PO-100191 | B192: 2025-02-25 | C192: SUP-01 | D192: SKU-1010 | E192: WH-BOM | F192: 129 | G192: 111237 | H192: 14349573 | I192: 2025-03-11 | J192: 2025-03-11 | K192: 129 | L192: 0 | M192: Delivered | N192: =TRIM(A192) -> PO-100191 | O192: =PROPER(TRIM(M192)) -> Delivered | P192: =TRIM(E192) -> WH-BOM | Q192: =VLOOKUP(C192, Lookups!$A$2:$D$10, 2, FALSE()) -> TechSupply Corp | R192: =_xlfn.XLOOKUP(D192, Lookups!$A$12:$A$51, Lookups!$C$12:$C$51, "Unknown") -> Electronics | S192: =IF(ISBLANK(I192), B192+VLOOKUP(C192, Lookups!$A$2:$D$10, 4, FALSE()), I192) -> 2025-03-11 | T192: =IF(ISBLANK(J192), "", J192-B192) -> 14 | U192: =IF(O192="Open", "Open", IF(J192>S192, "Late", "On-Time")) -> On-Time | V192: =IF(K192>0, L192/K192, 0) -> 0
A193: PO-100192 | B193: 2025-01-06 | C193: SUP-05 | D193: SKU-1025 | E193: WH-PUN | F193: 174 | G193: 26270 | H193: 4570980 | I193: 2025-01-24 | J193: 2025-01-24 | K193: 174 | L193: 0 | M193: Delivered | N193: =TRIM(A193) -> PO-100192 | O193: =PROPER(TRIM(M193)) -> Delivered | P193: =TRIM(E193) -> WH-PUN | Q193: =VLOOKUP(C193, Lookups!$A$2:$D$10, 2, FALSE()) -> FastElectronics | R193: =_xlfn.XLOOKUP(D193, Lookups!$A$12:$A$51, Lookups!$C$12:$C$51, "Unknown") -> Networking | S193: =IF(ISBLANK(I193), B193+VLOOKUP(C193, Lookups!$A$2:$D$10, 4, FALSE()), I193) -> 2025-01-24 | T193: =IF(ISBLANK(J193), "", J193-B193) -> 18 | U193: =IF(O193="Open", "Open", IF(J193>S193, "Late", "On-Time")) -> On-Time | V193: =IF(K193>0, L193/K193, 0) -> 0
A194: PO-100193 | B194: 2026-10-23 | C194: SUP-02 | D194: SKU-1034 | E194: WH-BOM | F194: 36 | G194: 16501 | H194: 594036 | I194: 2026-11-13 | J194: 2026-11-14 | K194: 36 | L194: 0 | M194: Delivered | N194: =TRIM(A194) -> PO-100193 | O194: =PROPER(TRIM(M194)) -> Delivered | P194: =TRIM(E194) -> WH-BOM | Q194: =VLOOKUP(C194, Lookups!$A$2:$D$10, 2, FALSE()) -> Global Networks | R194: =_xlfn.XLOOKUP(D194, Lookups!$A$12:$A$51, Lookups!$C$12:$C$51, "Unknown") -> Networking | S194: =IF(ISBLANK(I194), B194+VLOOKUP(C194, Lookups!$A$2:$D$10, 4, FALSE()), I194) -> 2026-11-13 | T194: =IF(ISBLANK(J194), "", J194-B194) -> 22 | U194: =IF(O194="Open", "Open", IF(J194>S194, "Late", "On-Time")) -> Late | V194: =IF(K194>0, L194/K194, 0) -> 0
A195: PO-100194 | B195: 2026-11-05 | C195: SUP-01 | D195: SKU-1010 | E195: WH-BOM | F195: 94 | G195: 111237 | H195: 10456278 | I195: 2026-11-19 | J195: 2026-11-28 | K195: 94 | L195: 0 | M195: Delivered | N195: =TRIM(A195) -> PO-100194 | O195: =PROPER(TRIM(M195)) -> Delivered | P195: =TRIM(E195) -> WH-BOM | Q195: =VLOOKUP(C195, Lookups!$A$2:$D$10, 2, FALSE()) -> TechSupply Corp | R195: =_xlfn.XLOOKUP(D195, Lookups!$A$12:$A$51, Lookups!$C$12:$C$51, "Unknown") -> Electronics | S195: =IF(ISBLANK(I195), B195+VLOOKUP(C195, Lookups!$A$2:$D$10, 4, FALSE()), I195) -> 2026-11-19 | T195: =IF(ISBLANK(J195), "", J195-B195) -> 23 | U195: =IF(O195="Open", "Open", IF(J195>S195, "Late", "On-Time")) -> Late | V195: =IF(K195>0, L195/K195, 0) -> 0
A196: PO-100195 | B196: 2025-02-25 | C196: SUP-07 | D196: SKU-1039 | E196: WH-DEL | F196: 115 | G196: 81434 | H196: 9364910 | I196: 2025-03-21 | J196: 2025-03-21 | K196: 115 | L196: 1 | M196: Delivered | N196: =TRIM(A196) -> PO-100195 | O196: =PROPER(TRIM(M196)) -> Delivered | P196: =TRIM(E196) -> WH-DEL | Q196: =VLOOKUP(C196, Lookups!$A$2:$D$10, 2, FALSE()) -> NextGen Hardware | R196: =_xlfn.XLOOKUP(D196, Lookups!$A$12:$A$51, Lookups!$C$12:$C$51, "Unknown") -> Electronics | S196: =IF(ISBLANK(I196), B196+VLOOKUP(C196, Lookups!$A$2:$D$10, 4, FALSE()), I196) -> 2025-03-21 | T196: =IF(ISBLANK(J196), "", J196-B196) -> 24 | U196: =IF(O196="Open", "Open", IF(J196>S196, "Late", "On-Time")) -> On-Time | V196: =IF(K196>0, L196/K196, 0) -> 0.0086956522
A197: PO-100196 | B197: 2026-06-10 | C197: SUP-01 | D197: SKU-1035 | E197: WH-BOM | F197: 142 | G197: 74871 | H197: 10631682 | I197: 2026-06-24 | J197: 2026-06-24 | K197: 142 | L197: 0 | M197: Delivered | N197: =TRIM(A197) -> PO-100196 | O197: =PROPER(TRIM(M197)) -> Delivered | P197: =TRIM(E197) -> WH-BOM | Q197: =VLOOKUP(C197, Lookups!$A$2:$D$10, 2, FALSE()) -> TechSupply Corp | R197: =_xlfn.XLOOKUP(D197, Lookups!$A$12:$A$51, Lookups!$C$12:$C$51, "Unknown") -> Electronics | S197: =IF(ISBLANK(I197), B197+VLOOKUP(C197, Lookups!$A$2:$D$10, 4, FALSE()), I197) -> 2026-06-24 | T197: =IF(ISBLANK(J197), "", J197-B197) -> 14 | U197: =IF(O197="Open", "Open", IF(J197>S197, "Late", "On-Time")) -> On-Time | V197: =IF(K197>0, L197/K197, 0) -> 0
A198: PO-100197 | B198: 2026-06-26 | C198: SUP-07 | D198: SKU-1011 | E198: WH-PUN | F198: 150 | G198: 48478 | H198: 7271700 | I198: 2026-07-20 | J198: 2026-08-04 | K198: 150 | L198: 0 | M198: Delivered | N198: =TRIM(A198) -> PO-100197 | O198: =PROPER(TRIM(M198)) -> Delivered | P198: =TRIM(E198) -> WH-PUN | Q198: =VLOOKUP(C198, Lookups!$A$2:$D$10, 2, FALSE()) -> NextGen Hardware | R198: =_xlfn.XLOOKUP(D198, Lookups!$A$12:$A$51, Lookups!$C$12:$C$51, "Unknown") -> Electronics | S198: =IF(ISBLANK(I198), B198+VLOOKUP(C198, Lookups!$A$2:$D$10, 4, FALSE()), I198) -> 2026-07-20 | T198: =IF(ISBLANK(J198), "", J198-B198) -> 39 | U198: =IF(O198="Open", "Open", IF(J198>S198, "Late", "On-Time")) -> Late | V198: =IF(K198>0, L198/K198, 0) -> 0
A199: PO-100198 | B199: 2026-06-24 | C199: SUP-06 | D199: SKU-1021 | E199: WH-BOM | F199: 179 | G199: 7754 | H199: 1387966 | I199: 2026-07-04 | J199: 2026-07-05 | K199: 179 | L199: 0 | M199: Delivered | N199: =TRIM(A199) -> PO-100198 | O199: =PROPER(TRIM(M199)) -> Delivered | P199: =TRIM(E199) -> WH-BOM | Q199: =VLOOKUP(C199, Lookups!$A$2:$D$10, 2, FALSE()) -> Peripheral Source | R199: =_xlfn.XLOOKUP(D199, Lookups!$A$12:$A$51, Lookups!$C$12:$C$51, "Unknown") -> Peripherals | S199: =IF(ISBLANK(I199), B199+VLOOKUP(C199, Lookups!$A$2:$D$10, 4, FALSE()), I199) -> 2026-07-04 | T199: =IF(ISBLANK(J199), "", J199-B199) -> 11 | U199: =IF(O199="Open", "Open", IF(J199>S199, "Late", "On-Time")) -> Late | V199: =IF(K199>0, L199/K199, 0) -> 0
...

Sheet Lookups
A1: Supplier_ID | B1: Supplier_Name | C1: Country | D1: Default_Lead_Time_Days
A2: SUP-01 | B2: TechSupply Corp | C2: India | D2: 14
A3: SUP-02 | B3: Global Networks | C3: Taiwan | D3: 21
A4: SUP-03 | B4: OfficeDepot Pro | C4: India | D4: 7
A5: SUP-04 | B5: MegaFurnish | C5: China | D5: 30
A6: SUP-05 | B6: FastElectronics | C6: Vietnam | D6: 18
A7: SUP-06 | B7: Peripheral Source | C7: India | D7: 10
A8: SUP-07 | B8: NextGen Hardware | C8: Taiwan | D8: 24
A9: SUP-08 | B9: Premium Desks Ltd | C9: India | D9: 12
A11: SKU | B11: Product_Name | C11: Category | D11: Unit_Cost_INR | E11: Primary_Supplier_ID
A12: SKU-1001 | B12: Pro Laptop Model U | C12: Electronics | D12: 59592 | E12: SUP-01
A13: SKU-1002 | B13: Pro Laptop Model A | C13: Electronics | D13: 81048 | E13: SUP-01
A14: SKU-1003 | B14: Enterprise Router 350X | C14: Networking | D14: 22314 | E14: SUP-05
A15: SKU-1004 | B15: Pro Laptop Model E | C15: Electronics | D15: 58434 | E15: SUP-07
A16: SKU-1005 | B16: Enterprise Router 792X | C16: Networking | D16: 39270 | E16: SUP-02
A17: SKU-1006 | B17: Wireless Headset 9 | C17: Peripherals | D17: 2212 | E17: SUP-06
A18: SKU-1007 | B18: Pro Laptop Model S | C18: Electronics | D18: 100302 | E18: SUP-05
A19: SKU-1008 | B19: Pro Laptop Model B | C19: Electronics | D19: 48905 | E19: SUP-01
A20: SKU-1009 | B20: Wireless Keyboard 2 | C20: Peripherals | D20: 3291 | E20: SUP-06
A21: SKU-1010 | B21: Pro Laptop Model H | C21: Electronics | D21: 111237 | E21: SUP-01
A22: SKU-1011 | B22: Pro Laptop Model T | C22: Electronics | D22: 48478 | E22: SUP-07
A23: SKU-1012 | B23: Pro Laptop Model R | C23: Electronics | D23: 71062 | E23: SUP-07
... A51: SKU-1040 | B51: Wireless Mouse 8 | C51: Peripherals | D51: 6707 | E51: SUP-06
A53: Warehouse_ID | B53: Location
A54: WH-BOM | B54: Mumbai Central
A55: WH-DEL | B55: Delhi North
A56: WH-BLR | B56: Bengaluru South
A57: WH-PUN | B57: Pune West

Sheet Methodology_QA
A1: Section | B1: Content
A2: 1. Tool Versions | B2: Generated via Python openpyxl for Excel compatibility. Formulas calculate upon opening.
A3: 2. Limitations | B3: PivotTables require manual creation from Cleaned_POs due to binary compilation restrictions in openpyxl.
A4: 3. Quality Checks | B4: Ground truth calculations verified. Duplicates (45) flagged. Text standardization via PROPER/TRIM applied.
